Workbook

Sheet 角色卡
B1: =IF(ISBLANK(C3), "⚔ XXX角色卡 ⚔", "⚔ " & C3 & "角色卡 ⚔")
B2: 基本信息 | H2: 🎒 装备 / 物品栏
B3: 角色姓名 | D3: 职业 | F3: 熟练加值 PB
B4: 玩家姓名 | D4: 子职业 | F4: 2
B5: 背景 | D5: 性别 | H5: 📝 角色简介
B6: 性格 | D6: 等级 | H6: 年龄: 身高: 体重: 外貌特征:
B8: 六围属性 (选择职业后自动填充推荐值)
B9: 属性 | C9: 基本数值 | D9: 属性增加 | E9: 当前数值 | F9: 调整值 Mod | H9: 豁免熟练 | I9: 豁免加值
B10: 力量 | C10: =IFERROR(INDEX(职业模板!$B$2:$B$8,MATCH($E$3,职业模板!$A$2:$A$8,0)),10) | D10: 0 | E10: =C10+D10 | F10: =ROUNDDOWN((E10-10)/2,0) | H10: =IFERROR(INDEX(职业模板!$H$2:$H$8,MATCH($E$3,职业模板!$A$2:$A$8,0)),0) | I10: =F10+(H10*$F$4)
B11: 速度 | C11: =IFERROR(INDEX(职业模板!$C$2:$C$8,MATCH($E$3,职业模板!$A$2:$A$8,0)),10) | D11: 0 | E11: =C11+D11 | F11: =ROUNDDOWN((E11-10)/2,0) | H11: =IFERROR(INDEX(职业模板!$I$2:$I$8,MATCH($E$3,职业模板!$A$2:$A$8,0)),0) | I11: =F11+(H11*$F$4)
B12: 耐力 | C12: =IFERROR(INDEX(职业模板!$D$2:$D$8,MATCH($E$3,职业模板!$A$2:$A$8,0)),10) | D12: 0 | E12: =C12+D12 | F12: =ROUNDDOWN((E12-10)/2,0) | H12: =IFERROR(INDEX(职业模板!$J$2:$J$8,MATCH($E$3,职业模板!$A$2:$A$8,0)),0) | I12: =F12+(H12*$F$4)
B13: 控制 | C13: =IFERROR(INDEX(职业模板!$E$2:$E$8,MATCH($E$3,职业模板!$A$2:$A$8,0)),10) | D13: 0 | E13: =C13+D13 | F13: =ROUNDDOWN((E13-10)/2,0) | H13: =IFERROR(INDEX(职业模板!$K$2:$K$8,MATCH($E$3,职业模板!$A$2:$A$8,0)),0) | I13: =F13+(H13*$F$4)
B14: 精密 | C14: =IFERROR(INDEX(职业模板!$F$2:$F$8,MATCH($E$3,职业模板!$A$2:$A$8,0)),10) | D14: 0 | E14: =C14+D14 | F14: =ROUNDDOWN((E14-10)/2,0) | H14: =IFERROR(INDEX(职业模板!$L$2:$L$8,MATCH($E$3,职业模板!$A$2:$A$8,0)),0) | I14: =F14+(H14*$F$4)
B15: 魅力 | C15: =IFERROR(INDEX(职业模板!$G$2:$G$8,MATCH($E$3,职业模板!$A$2:$A$8,0)),10) | D15: 0 | E15: =C15+D15 | F15: =ROUNDDOWN((E15-10)/2,0) | H15: =IFERROR(INDEX(职业模板!$M$2:$M$8,MATCH($E$3,职业模板!$A$2:$A$8,0)),0) | I15: =F15+(H15*$F$4)
B17: 战斗数据 Combat Stats
B18: 护甲等级 AC | C18: =IFERROR(INDEX(职业模板!$O$2:$O$8,MATCH($E$3,职业模板!$A$2:$A$8,0)),10)+F11 | D18: 先攻 Initiative | E18: =F11 | F18: 速度 Speed (ft) | H18: =IFERROR(VLOOKUP(IF(ISBLANK(E4), E3, E4), '职业模板'!$W$2:$X$50, 2, 0), 30)
B19: 最大HP Max | D19: 当前HP Current | F19: 临时HP Temp
B20: 生命驰 Hit Dice | C20: =IFERROR(INDEX(职业模板!$N$2:$N$8,MATCH($E$3,职业模板!$A$2:$A$8,0)),"d8") | D20: 死亡豁免成功 ☑ | F20: 死亡豁免失败 ☒
B22: 被动察觉 Passive Perception | D22: =10+H49
B24: 斗气槽
C25: 槽 1 | D25: 槽 2 | E25: 槽 3 | F25: 槽 4 | H25: 槽 5 | I25: 槽 6
C26: ■ | D26: ■ | E26: ■ | F26: ■ | H26: ■ | I26: ■
B27: 攻击与施法 Attacks & Spellcasting
B28: 武器 / 法术名称 | D28: 攻击加值 | F28: 伤害 / 类型 | H28: 📝 攻击/施法补充说明
B36: 技能 Skills
B37: 技能 | C37: 关联属性 | D37: 熟练 ☐ | H37: 技能总值
B38: 特技 Acrobatics | C38: DEX | D38: FALSE | H38: =F11+IF(D38=TRUE,2,0)
B39: 动物驯养 Animal Handling | C39: WIS | D39: FALSE | H39: =F14+IF(D39=TRUE,2,0)
B40: 奥秘 Arcana | C40: INT | D40: FALSE | H40: =F13+IF(D40=TRUE,2,0)
B41: 运动 Athletics | C41: STR | D41: FALSE | H41: =F10+IF(D41=TRUE,2,0)
B42: 欺瞒 Deception | C42: CHA | D42: FALSE | H42: =F15+IF(D42=TRUE,2,0)
B43: 历史 History | C43: INT | D43: FALSE | H43: =F13+IF(D43=TRUE,2,0)
B44: 洞悉 Insight | C44: WIS | D44: FALSE | H44: =F14+IF(D44=TRUE,2,0)
B45: 威吓 Intimidation | C45: CHA | D45: FALSE | H45: =F15+IF(D45=TRUE,2,0)
B46: 调查 Investigation | C46: INT | D46: FALSE | H46: =F13+IF(D46=TRUE,2,0)
B47: 医药 Medicine | C47: WIS | D47: FALSE | H47: =F14+IF(D47=TRUE,2,0)
B48: 自然 Nature | C48: INT | D48: FALSE | H48: =F13+IF(D48=TRUE,2,0)
B49: 察觉 Perception | C49: WIS | D49: FALSE | H49: =F14+IF(D49=TRUE,2,0)
B50: 表演 Performance | C50: CHA | D50: FALSE | H50: =F15+IF(D50=TRUE,2,0)
B51: 游说 Persuasion | C51: CHA | D51: FALSE | H51: =F15+IF(D51=TRUE,2,0)
...

Sheet 职业模板
A1: 职业 | B1: STR 力量 | C1: DEX 速度 | D1: CON 耐力 | E1: INT 控制 | F1: WIS 精密 | G1: CHA 魅力 | H1: 豁STR | I1: 豁DEX | J1: 豁CON | K1: 豁INT | L1: 豁WIS | M1: 豁CHA | N1: 生命驰 | O1: AC基数 | T1: 查询键 (职业|子职业) | U1: 职业特性文本 | W1: 职业/子职业 | X1: 默认速度
A2: 武道者 | B2: 15 | C2: 10 | D2: 14 | E2: 12 | F2: 13 | G2: 8 | H2: 1 | I2: 1 | J2: 0 | K2: 0 | L2: 0 | M2: 0 | N2: d8 | O2: 10 | P2: 正统派 | Q2: 邪修派 | R2: 隐士 | T2: 武道者| | U2: 【1级】 上升攻击(Upper Cut): 武道者自带的必杀技，与“升龙拳”类似，消耗1个动作，造成等同于你重攻击的伤害，击中敌人后造成强制倒地。该招式如果没有命中会进入受击“确反康”的状态。在受到跳跃攻击时可以以反应使用，成功时对方的该次跳跃攻击将不会造成伤害，但失败依然会进入受击“确反康”状态。如果在“倒地”或者“强制倒地“时成为近战攻击的目标，则可以以反应释放该技能的od版本（可以选择消耗“反应”或“斗气槽”）。 【1级】 自在极意: 上升攻击作为武道者的核心技能，每场战斗中，每次成功使用会使其基础伤害增加2，但角色每次濒死/死亡/眩晕都会重置此修正，战斗结束后重置此修正。 【1级】 气定神闲: 通过反应释放， 武道者受到徒手攻击伤害时可以获得一个1d4的伤害衰减修正。 | W2: 武道者 | X2: 30
A3: 军士 | B3: 13 | C3: 14 | D3: 10 | E3: 15 | F3: 12 | G3: 8 | H3: 1 | I3: 0 | J3: 1 | K3: 0 | L3: 0 | M3: 0 | N3: d10 | O3: 13 | P3: 技巧型 | Q3: 力量型 | R3: 灵动型 | T3: 武道者|正统派 | U3: 【1级】 上升攻击(Upper Cut): 武道者自带的必杀技，与“升龙拳”类似，消耗1个动作，造成等同于你重攻击的伤害，击中敌人后造成强制倒地。该招式如果没有命中会进入受击“确反康”的状态。在受到跳跃攻击时可以以反应使用，成功时对方的该次跳跃攻击将不会造成伤害，但失败依然会进入受击“确反康”状态。如果在“倒地”或者“强制倒地“时成为近战攻击的目标，则可以以反应释放该技能的od版本（可以选择消耗“反应”或“斗气槽”）。 【1级】 自在极意: 上升攻击作为武道者的核心技能，每场战斗中，每次成功使用会使其基础伤害增加2，但角色每次濒死/死亡/眩晕都会重置此修正，战斗结束后重置此修正。 【1级】 气定神闲: 通过反应释放， 武道者受到徒手攻击伤害时可以获得一个1d4的伤害衰减修正。 【1级】 身法: 对手的徒手攻击如果未能命中你，一回合内，你对其攻击产生“确反康”并获得优势掷骰；对手的飞行道具如果未能命中你，你下个飞行道具必定会命中该对手。 【1级】 步法: 你使用普通技之后可以无消耗的移动5尺，且不会触发借机攻击。 【8级解锁】 登峰造极: 正统派的上升攻击后取消超级必杀技时，该场战斗剩余时间里上升攻击会造成双倍伤害。 | W3: 正统派 | X3: 30
A4: 蛮勇斗士 | B4: 14 | C4: 10 | D4: 15 | E4: 13 | F4: 12 | G4: 8 | H4: 1 | I4: 0 | J4: 1 | K4: 0 | L4: 0 | M4: 0 | N4: d12 | O4: 10 | P4: 摔角手 | Q4: 丛林猎手 | R4: 推土机 | T4: 武道者|邪修派 | U4: 【1级】 上升攻击(Upper Cut): 武道者自带的必杀技，与“升龙拳”类似，消耗1个动作，造成等同于你重攻击的伤害，击中敌人后造成强制倒地。该招式如果没有命中会进入受击“确反康”的状态。在受到跳跃攻击时可以以反应使用，成功时对方的该次跳跃攻击将不会造成伤害，但失败依然会进入受击“确反康”状态。如果在“倒地”或者“强制倒地“时成为近战攻击的目标，则可以以反应释放该技能的od版本（可以选择消耗“反应”或“斗气槽”）。 【1级】 自在极意: 上升攻击作为武道者的核心技能，每场战斗中，每次成功使用会使其基础伤害增加2，但角色每次濒死/死亡/眩晕都会重置此修正，战斗结束后重置此修正。 【1级】 气定神闲: 通过反应释放， 武道者受到徒手攻击伤害时可以获得一个1d4的伤害衰减修正。 【1级】 走火入魔: 你的所有攻击都会获得优势骰，所有受击都会陷入劣势骰。 【1级】 修罗之道: 击杀会获得2+1d6的生命值恢复。溢出部分会转化为临时生命值。 【1级】 你再看看你后面呢: 你在对手身后/视野之外发动的进攻会获得额外10尺的距离。以此方法发动的攻击必定命中，攻击时会闪身到对手身旁。脆弱的对手会“受惊”。 【1级】 跑快快！: 邪修派武道者获得额外10尺的移动距离。 【8级解锁】 彻底疯狂: 你释放超级必杀技后会陷入“修罗”状态：所有攻击必定会命中，所有受击也必定会命中。必杀技取消不会有伤害修正。角色濒死/死亡/眩晕后结束。战斗结束后也会结束此状态。 | W4: 邪修派 | X4: 40
A5: 刽子手 | B5: 12 | C5: 13 | D5: 8 | E5: 15 | F5: 14 | G5: 10 | H5: 0 | I5: 1 | J5: 0 | K5: 1 | L5: 0 | M5: 0 | N5: d8 | O5: 11 | P5: 刺杀者 | Q5: 荣誉行刑官 | T5: 武道者|隐士 | U5: 【1级】 上升攻击(Upper Cut): 武道者自带的必杀技，与“升龙拳”类似，消耗1个动作，造成等同于你重攻击的伤害，击中敌人后造成强制倒地。该招式如果没有命中会进入受击“确反康”的状态。在受到跳跃攻击时可以以反应使用，成功时对方的该次跳跃攻击将不会造成伤害，但失败依然会进入受击“确反康”状态。如果在“倒地”或者“强制倒地“时成为近战攻击的目标，则可以以反应释放该技能的od版本（可以选择消耗“反应”或“斗气槽”）。 【1级】 自在极意: 上升攻击作为武道者的核心技能，每场战斗中，每次成功使用会使其基础伤害增加2，但角色每次濒死/死亡/眩晕都会重置此修正，战斗结束后重置此修正。 【1级】 气定神闲: 通过反应释放， 武道者受到徒手攻击伤害时可以获得一个1d4的伤害衰减修正。 【1级】 独门绝技: 隐士拥有自己的一个独门绝技（为角色基础必杀技，玩家可以自行设计），该技能对第一次见到的对手必定命中，且必定造成最大命中伤害，无法被反应。 【1级】 不被世人关注的存在感: 战斗中，如果隐士连续两回合没有造成和受到伤害，隐士会进入“隐身”。直到发起进攻，受到范围伤害，或者被隐身感知观察到。 【8级解锁】 高级隐身: 隐士使用超级必杀技后会进入“高级隐身”，持续至多2个回合，其中即使造成和受到伤害也不会现身，且下次使用的独门绝技将会视为对手第一次见到此技。 | W5: 隐士 | X5: 30
A6: 牵制者 | B6: 8 | C6: 12 | D6: 10 | E6: 14 | F6: 15 | G6: 13 | H6: 0 | I6: 0 | J6: 0 | K6: 0 | L6: 1 | M6: 1 | N6: d8 | O6: 10 | P6: 重炮手 | Q6: 速射手 | T6: 军士| | U6: 【1级】 专业素养: 军士不会轻易受到言语上的挑衅，也不会受到魅惑。抵抗来自此类技能效果的减益会获得优势检定（=对手获得劣势检定）。 【1级】 无间配合: 军士非常擅长协同作战。你命中其他队友打入特殊状态的敌人会将其击飞。如果是两个军士在一回合内命中同一个目标时，该敌人还会受到额外的1+1d6的伤害。 【1级】 不屈: 军士受过严酷的意志力训练，体力值归0时不会倒地濒死而是继续作战。2回合内受到治疗，或者击杀1名敌人，则会从此状态恢复。再次受到伤害，或者2回合后如果未能取得击杀，则会直接死亡。不屈时，军士移动力减半，但攻击会获得优势命中。每场战斗可以重复触发。 | W6: 军士 | X6: 30
A7: 影罗残党 | B7: 13 | C7: 8 | D7: 10 | E7: 15 | F7: 14 | G7: 12 | H7: 0 | I7: 1 | J7: 0 | K7: 0 | L7: 1 | M7: 0 | N7: d10 | O7: 11 | P7: 统领 | Q7: 教头 | R7: 黑手 | T7: 军士|技巧型 | U7: 【1级】 专业素养: 军士不会轻易受到言语上的挑衅，也不会受到魅惑。抵抗来自此类技能效果的减益会获得优势检定（=对手获得劣势检定）。 【1级】 无间配合: 军士非常擅长协同作战。你命中其他队友打入特殊状态的敌人会将其击飞。如果是两个军士在一回合内命中同一个目标时，该敌人还会受到额外的1+1d6的伤害。 【1级】 不屈: 军士受过严酷的意志力训练，体力值归0时不会倒地濒死而是继续作战。2回合内受到治疗，或者击杀1名敌人，则会从此状态恢复。再次受到伤害，或者2回合后如果未能取得击杀，则会直接死亡。不屈时，军士移动力减半，但攻击会获得优势命中。每场战斗可以重复触发。 【1级】 连续技: 每回合，对陷入特殊状态的对手可以使用一次无消耗的非OD版本必杀技。该必杀技会有(1d6 -熟练项调整)的惩罚。 【1级】 斗气连携: 使用OD必杀技之后的一回合内，所有OD技只会消耗1格斗气。 【8级解锁】 完美谢幕: 你的超级必杀技必定命中特殊状态的敌人（包括强制倒地）。本场战斗中每次使用必杀技都会使超级必杀技增加2点伤害（且该部分伤害不会被修正影响）。 | W7: 技巧型 | X7: 30
A8: 道具师 | B8: 12 | C8: 14 | D8: 10 | E8: 8 | F8: 15 | G8: 13 | H8: 0 | I8: 0 | J8: 1 | K8: 1 | L8: 0 | M8: 0 | N8: d8 | O8: 10 | P8: 特工 | Q8: 影 | T8: 军士|力量型 | U8: 【1级】 专业素养: 军士不会轻易受到言语上的挑衅，也不会受到魅惑。抵抗来自此类技能效果的减益会获得优势检定（=对手获得劣势检定）。 【1级】 无间配合: 军士非常擅长协同作战。你命中其他队友打入特殊状态的敌人会将其击飞。如果是两个军士在一回合内命中同一个目标时，该敌人还会受到额外的1+1d6的伤害。 【1级】 不屈: 军士受过严酷的意志力训练，体力值归0时不会倒地濒死而是继续作战。2回合内受到治疗，或者击杀1名敌人，则会从此状态恢复。再次受到伤害，或者2回合后如果未能取得击杀，则会直接死亡。不屈时，军士移动力减半，但攻击会获得优势命中。每场战斗可以重复触发。 【1级】 塔盾: 消耗80%的移动力。1个回合内，你会携带“霸体”。霸体状态角色的行动无法被反应。霸体角色受到的强制位移会被显著削弱。 【1级】 当身: 近战攻击命中你的“霸体状态”时，攻击者会受到一个等同于你轻攻击的伤害，并进行一个体质检定，如果检定失败，你对其下次攻击会处于优势。 【1级】 谁需要来一记重拳！: 你击飞的敌人会飞的更高。你造成特殊状态时，会对对手造成一个额外的（1d4+力量调整）的伤害。 【8级解锁】 猛然冲击: 你的超级必杀技会给予你持续2回合的“霸体”。位于你超级必杀技释放路径/范围内的所有其他敌人都会受到30%的该超级必杀技伤害。 | W8: 力量型 | X8: 30
T9: 军士|灵动型 | U9: 【1级】 专业素养: 军士不会轻易受到言语上的挑衅，也不会受到魅惑。抵抗来自此类技能效果的减益会获得优势检定（=对手获得劣势检定）。 【1级】 无间配合: 军士非常擅长协同作战。你命中其他队友打入特殊状态的敌人会将其击飞。如果是两个军士在一回合内命中同一个目标时，该敌人还会受到额外的1+1d6的伤害。 【1级】 不屈: 军士受过严酷的意志力训练，体力值归0时不会倒地濒死而是继续作战。2回合内受到治疗，或者击杀1名敌人，则会从此状态恢复。再次受到伤害，或者2回合后如果未能取得击杀，则会直接死亡。不屈时，军士移动力减半，但攻击会获得优势命中。每场战斗可以重复触发。 【1级】 奇袭: 你从与对手不同地形位置发起的进攻具有优势。你擅长在各种地形上移动（不会消耗额外移动力）。 【1级】 飞檐走壁: 你可以在墙壁/天花板等类似地形停留最多一个回合。 【1级】 跑快快！: 速度型军士获得额外10尺的移动距离。 【8级解锁】 红色delta强袭: 在特殊地形时：你可以在队友攻击后释放你的超级必杀技。若如此做，你的超级必杀技必定会命中对手，但是队友回合会就此结束，你可以开始一个新的回合。如果你是队伍中唯一存活的角色，你可以在任意角色行动时释放你的超级必杀技。 | W9: 灵动型 | X9: 40
T10: 蛮勇斗士| | U10: 【1级】 暴力本能: 蛮勇斗士可以以一个附赠动作进入“狂暴”状态，每次长休后你可使用的狂暴次数等于（你的等级/3）+1。狂暴状态时，你的普通技都会等同于附带最大可使用狂暴状态次数的伤害；你的力量检定和力量豁免具有优势；拥有对轻/中攻击的抗性（受到伤害为50%）。“狂暴”状态的角色无法使用飞行道具。如果角色被击晕，强制倒地，或者一回合内未造成/受到伤害，狂暴状态解除。你也可以主动结束狂暴状态。 【1级】 凶蛮重击: 你的普通技重击可以获得一个额外的伤害骰子（等同于该动作所使用的骰子）。8级时你可以再获得一个。 | W10: 蛮勇斗士 | X10: 30
T11: 蛮勇斗士|摔角手 | U11: 【1级】 暴力本能: 蛮勇斗士可以以一个附赠动作进入“狂暴”状态，每次长休后你可使用的狂暴次数等于（你的等级/3）+1。狂暴状态时，你的普通技都会等同于附带最大可使用狂暴状态次数的伤害；你的力量检定和力量豁免具有优势；拥有对轻/中攻击的抗性（受到伤害为50%）。“狂暴”状态的角色无法使用飞行道具。如果角色被击晕，强制倒地，或者一回合内未造成/受到伤害，狂暴状态解除。你也可以主动结束狂暴状态。 【1级】 凶蛮重击: 你的普通技重击可以获得一个额外的伤害骰子（等同于该动作所使用的骰子）。8级时你可以再获得一个。 【1级】 歌莉娅巨人: 你的“狂暴”会让你的身形变大。巨大化时受到位移效果显著降低；你可以轻松举起比你体型小的敌人，对这类敌人的指令投技能具有优势。会随着体型与对手体型的差值获得更多优势（由dm描述决定）。 【1级】 坦克引擎: 你的指令投系技能击杀对手时会获得3点最大生命值。 【8级解锁】 大爆炸: 你的超级必杀技必定会命中体型小于你的敌人。在剩余战斗时间里你的体型会保持巨大化（可以与狂暴巨大叠加），且力量会直接升至21。 | W11: 摔角手 | X11: 30
T12: 蛮勇斗士|丛林猎手 | U12: 【1级】 暴力本能: 蛮勇斗士可以以一个附赠动作进入“狂暴”状态，每次长休后你可使用的狂暴次数等于（你的等级/3）+1。狂暴状态时，你的普通技都会等同于附带最大可使用狂暴状态次数的伤害；你的力量检定和力量豁免具有优势；拥有对轻/中攻击的抗性（受到伤害为50%）。“狂暴”状态的角色无法使用飞行道具。如果角色被击晕，强制倒地，或者一回合内未造成/受到伤害，狂暴状态解除。你也可以主动结束狂暴状态。 【1级】 凶蛮重击: 你的普通技重击可以获得一个额外的伤害骰子（等同于该动作所使用的骰子）。8级时你可以再获得一个。 【1级】 猿神启动: 你的狂暴会让你身上流淌一种自然元素（毒，冰，火，电，选1），你的近战攻击会携带该元素效果并以该元素伤害作为额外狂暴伤害。 【1级】 野性: 你对敌人造成的元素效果伤害可以叠加，对手回合开始时会进行体质豁免检定，没有通过则会保留层数，通过则会重置。每个元素分别对应以下效果： a.毒：每回合受1d6+体质熟练的毒伤害。5层触发毒爆，对10尺内敌造成1d10+熟练毒伤害。 b.冰：每层减20%移动。5层触发冰暴，束缚10尺内敌造1d10+熟练伤害。 c.火：移动痕迹留火，对经过者造1d6+熟练燃烧伤。5层触发爆炸，造1d20+熟练伤害，火留3回合。 d.电：每层1d4+熟练闪电伤害。多带电敌人受连锁总层数伤害。场上总5层引发雷电猛击：眩晕1回并受1d10+熟练伤害。 【8级解锁】 野性爆发: 使用超级必杀技后，你可以选择一种自然元素并保留该元素效果直至该场战斗结束，可以与猿神启动叠加（你可以选两个一样元素来达到双倍叠层，或者不同元素来达到多重效果）。 | W12: 丛林猎手 | X12: 30
T13: 蛮勇斗士|推土机 | U13: 【1级】 暴力本能: 蛮勇斗士可以以一个附赠动作进入“狂暴”状态，每次长休后你可使用的狂暴次数等于（你的等级/3）+1。狂暴状态时，你的普通技都会等同于附带最大可使用狂暴状态次数的伤害；你的力量检定和力量豁免具有优势；拥有对轻/中攻击的抗性（受到伤害为50%）。“狂暴”状态的角色无法使用飞行道具。如果角色被击晕，强制倒地，或者一回合内未造成/受到伤害，狂暴状态解除。你也可以主动结束狂暴状态。 【1级】 凶蛮重击: 你的普通技重击可以获得一个额外的伤害骰子（等同于该动作所使用的骰子）。8级时你可以再获得一个。 【1级】 大力士: 你的“狂暴“会让你的所有攻击附带”击退“效果，无论是否造成伤害（但”挥空“时不会推开）。你的”击退“会与地形产生互动。击退的距离与攻击方式，攻击强度，和对手体型相关（由dm描述决定）。如果你攻击本身就附带特殊状态效果，则不会击退。对已经处于特殊状态（如浮空，倒地等）的角色产生的击退效果更强，与地形的互动也会更有效。 【1级】 几何学: 通过反应施放，如果附近有一名角色被击退到你附近你可以对他们再一次进行击退（可以随意选择方向），造成等同于他们上次击退受到的伤害。 【8级解锁】 天崩地裂: 你的超级必杀技会在目标角色周围砸出一个直径20尺的圆形墙壁地形，持续到你或者目标死亡（可被破坏或者局部破坏）。如果在室内释放，则会将该部分区域强制转化为直径20尺的竞技场。所有与该墙壁互动的角色都会受到额外的1d6的伤害。 | W13: 推土机 | X13: 30
T14: 刽子手| | U14: 【1级】 最后一击: 每场战斗开始时刽子手会进行一个“处决”判定（1d4+力量熟练调整），如果刽子手的攻击使一名角色血量降低至该处决值以下，则会直接击杀该目标，并获得来自x公司的金钱提成（取决于击杀目标的价值）。 【1级】 背刺: 从身后/未被发现/先攻时发起的进攻会附带优势，并造成额外的1d6的伤害（每回合最多一次）。 | W14: 刽子手 | X14: 30
T15: 刽子手|刺杀者 | U15: 【1级】 最后一击: 每场战斗开始时刽子手会进行一个“处决”判定（1d4+力量熟练调整），如果刽子手的攻击使一名角色血量降低至该处决值以下，则会直接击杀该目标，并获得来自x公司的金钱提成（取决于击杀目标的价值）。 【1级】 背刺: 从身后/未被发现/先攻时发起的进攻会附带优势，并造成额外的1d6的伤害（每回合最多一次）。 【1级】 终结标记: 你每次必杀技命中时都会获得1个1d6的“终结骰“，你可以在之后的必杀技命中时选择是否使用。使用时，会消耗所有已积攒的”终结骰“来对对手造成额外伤害。终结骰最多可以积攒5个。 【1级】 余罪赦免: 你受到致命伤害时，可以消耗所有的“终结骰“，你恢复到该数量的生命值。每次长休只能触发一次。 【8级解锁】 终审 · 命定之死: 释放超级必杀技后，你所有的“终结骰“会升级成每个1d10的骰子，持续到战斗结束。 | W15: 刺杀者 | X15: 35
T16: 刽子手|荣誉行刑官 | U16: 【1级】 最后一击: 每场战斗开始时刽子手会进行一个“处决”判定（1d4+力量熟练调整），如果刽子手的攻击使一名角色血量降低至该处决值以下，则会直接击杀该目标，并获得来自x公司的金钱提成（取决于击杀目标的价值）。 【1级】 背刺: 从身后/未被发现/先攻时发起的进攻会附带优势，并造成额外的1d6的伤害（每回合最多一次）。 | W16: 荣耀行刑官 | X16: 30
T17: 牵制者| | U17: 【1级】 火力覆盖: 你的飞行道具系必杀技可以通过附赠动作释放。你飞行道具系必杀技的od版本只消耗1格斗气槽。 【1级】 射击专精: 可开关状态，不能在同一回合内同时开关。你对15尺以外的无掩体敌人的攻击带有优势。5尺以内的敌人对你的攻击带有优势。 | W17: 牵制者 | X17: 30
T18: 牵制者|重炮手 | U18: 【1级】 火力覆盖: 你的飞行道具系必杀技可以通过附赠动作释放。你飞行道具系必杀技的od版本只消耗1格斗气槽。 【1级】 射击专精: 可开关状态，不能在同一回合内同时开关。你对15尺以外的无掩体敌人的攻击带有优势。5尺以内的敌人对你的攻击带有优势。 【1级】 让子弹飞一会: 你所有的非od的飞行道具系必杀技会在你释放之后缓慢飞行，追踪并在对手回合开始时命中对手（在轮到其回合时进行命中及伤害判定）。所有在此期间提前触碰到的敌人会直接被该道具命中。 【1级】 范围轰炸: 你的飞行道具系必杀技会对命中对手及其附近3尺半径内所有敌人造成伤害，非直接命中的敌人受到一半伤害。 【1级】 炮架: 可开关状态，不能在同一回合内同时开关。你失去75%移动力并将其转换为额外飞行道具系必杀技的攻击距离；同时范围伤害半径扩大到6尺。 【8级解锁】 炮火连天: 释放超级必杀技后你会对场上所有敌人释放一个飞行道具系必杀技。如果一个敌人受到了两次来自不同飞行道具的伤害，会受到一次额外的1d10+控制熟练的伤害。 | W18: 重炮手 | X18: 25
T19: 牵制者|速射手 | U19: 【1级】 火力覆盖: 你的飞行道具系必杀技可以通过附赠动作释放。你飞行道具系必杀技的od版本只消耗1格斗气槽。 【1级】 射击专精: 可开关状态，不能在同一回合内同时开关。你对15尺以外的无掩体敌人的攻击带有优势。5尺以内的敌人对你的攻击带有优势。 【1级】 穿透射击: 你所有的非od的飞行道具系必杀技会在你释放之后迅速到达对手处，穿透所有经过的敌人。非主要目标会受到50%的伤害。无论是否命中，受影响的敌人会被击退到弹道两旁（无法产生与地形互动）。 【1级】 连发: 如果你释放的飞行道具系必杀技命中至少两名敌人，或者造成重击伤害，你可以无消耗的再释放一次。可以重复触发。 【1级】 枪托: 可开关状态，不能在同一回合内同时开关。你的飞行道具系必杀技不会向两旁击退而是向正后方，但每次释放会额外消耗20%移动力。 【8级解锁】 全自动模式: 释放超级必杀技后，你每回合开始时会向最近的敌人自动发射一个飞行道具，可以触发连发。 | W19: 速射手 | X19: 35
T20: 影罗残党| | U20: 【1级】 精神力: 你所有类型的必杀技都会附带1d4+控制熟练的心灵伤害。受到心灵伤害的对手会被施加一层“精神萎靡”。处于精神萎靡的单位会丧失斗志，所有攻击附带-1的伤害修正，最多叠加5层。 【1级】 精神力防御: 你对心灵伤害有抗性，受到心灵伤害减半。 【8级解锁】 领域展开: 所有影罗残党的超级必杀技都会变更为“领域展开”。无需进行命中判定，你将会和最多2名对手进入精神力领域。期间你每回合会失去一格斗气，斗气枯竭时领域结束。你的所有攻击必定命中领域中的对手，且“精神萎靡”状态可以被叠加到最多10层，达到10层的对手会立刻死亡。如果场上有超过1个领域同时展开，则会抵消相互剩余斗气，直到一方斗气枯竭，留下另一方的领域。 | W20: 影罗残党 | X20: 30
... T26: 道具师|影 | U26: 【1级】 不公平对战: 道具师们被允许使用他们专属的道具/武器进行战斗。他们所有的必杀技会根据所使用的武器造成特殊状态。但你的普通技无法使用武器。 【1级】 异次元口袋: 你会获得一个异次元双肩背包。你可以在背包里装任意数量、重量的单位，但大小不得超过你背包大小。 【1级】 手工达人: 你可以通过收集各种材料进行合成，根据你所受击的材料进行掷骰，根据结果会获得不一样的战斗中可使用的消耗品。 【1级】 契约武器: 你可以选择一件物品为契约武器，每次长休后可以选择一次。你的必杀技可以使用你的契约武器进行伤害，可以根据武器特性造成特殊效果。每次使用都会累计一点熟练度。达到25层时，该武器会获得一种元素属性（毒，冰，火，电，选1）。达到50层时，该武器造成的额外伤害翻倍。达到75层时，即使没有命中也会造成武器的额外伤害。达到100层时，该武器达到满级，所有伤害会重击且命中必带优势，即使没有绑定也可以召唤出来使用。切换绑定武器不会损失之前叠加的层数。 【1级】 大击靶: 你可以投掷一个物品并在空中用你的契约武器对其进行打击。使该物品的效果扩散到被击中区域内所有单位，并对敌人造成该武器的额外伤害。 【8级解锁】 天人合一: 释放超级必杀技之后，你手中的武器会短暂升到满级，持续到战斗结束。 | W26: 影 | X26: 35

Sheet 专长参考
A1: 等级 | B1: 专长名称 | C1: 效果描述
A2: 3级 | B2: 波动之拳 | C2: 你回合内的第一次释放的飞行道具未命中时不消耗任何资源。你的飞行道具造成额外的1d4+（控制调整）伤害。
A3: 3级 | B3: 瑜伽之手 | C3: 你的轻/中/重攻击可以拥有额外的4/6/10尺攻击范围，若如此做，此次普通技无法取消必杀技。命中时将对手推开1/2/3尺。
A4: 3级 | B4: 立回专家 | C4: 未命中你的普通技命中掷骰如果小于你的AC值 – 5, 此次攻击将会“挥空”。挥空的对手无法取消此次普通技，且该回合内下次受击将处于“确反康”状态。2尺内的对手对你使用的重攻击拥有劣势掷骰。
A5: 3级 | B5: 扫堂腿 | C5: 你获得一个额外的特殊技，扫堂腿：主动释放时消耗一个动作，对5尺内的一个敌人施展下段重攻击扫腿，使其收到1d10+（力量调整）的伤害并强制倒地。该特殊技也会替代你的“借机攻击”，消耗一个反应且无法被闪避。无法取消必杀技
A6: 3级 | B6: 蓝精灵 | C6: 完美防御可对你的完美防御判定也可以为对手命中判定掷筛的+1或者-1。你从完美防御获得的攻击机会将不会有伤害修正。
A7: 3级 | B7: 恐怖投手 | C7: 你会恢复来自你指令投系技能伤害50%的生命值。你的指令投落空后如果没有被 “确反康“，你会获得1+1d6点临时生命值。
A8: 3级 | B8: 白色恐惧 | C8: 你在斗气枯竭时可以通过反应来对未命中你的对手释放一次必杀技。你在斗气枯竭时不会被敌方角色强制移动。
A9: 3级 | B9: 偷偷乐 | C9: 来自你普通技的中段攻击必定命中一轮行动内没有移动过的敌人。该次攻击不会消耗你的动作或者附赠动作。
A10: 3级 | B10: 热血沸腾的组合技! | C10: 当你命中一个被队友打入特殊状态的敌人时，会延长该状态的持续时间，直到你结束回合或施加一个新的状态（普通技不会使其强制倒地）。
A11: 3级 | B11: 猜拳王 | C11: 你对一回合内强制倒地过的敌人具有优势。你被强制倒地后的一回合内敌人对你的攻击具有劣势。
A12: 3级 | B12: 凹比 | C12: 你可以通过反应使用两格斗气来释放一次必杀技（或者直接使用超级必杀技！）来反击一次敌人的近战攻击，“凹“：成功命中时，你不会受到此次攻击的伤害并造成你必杀技伤害，并结束对方回合。未命中时，敌人的攻击将会打出“确反康“。
... A31: 🔵 3级专长 | B31: 🟢 5级专长 | C31: 🟠 8级专长

Sheet 职业特性
A1: 职业 | B1: 通用特性 (等级) | C1: 通用特性说明 | D1: 子职业 | E1: 子职业特性 (等级) | F1: 子职业特性说明
A2: 武道者 | B2: 1级 | 上升攻击(Upper Cut) | C2: 武道者自带的必杀技，与“升龙拳”类似，消耗1个动作，造成等同于你重攻击的伤害，击中敌人后造成强制倒地。该招式如果没有命中会进入受击“确反康”的状态。在受到跳跃攻击时可以以反应使用，成功时对方的该次跳跃攻击将不会造成伤害，但失败依然会进入受击“确反康”状态。如果在“倒地”或者“强制倒地“时成为近战攻击的目标，则可以以反应释放该技能的od版本（可以选择消耗“反应”或“斗气槽”）。 | D2: 正统派 | E2: 1级 | 身法 | F2: 对手的徒手攻击如果未能命中你，一回合内，你对其攻击产生“确反康”并获得优势掷骰；对手的飞行道具如果未能命中你，你下个飞行道具必定会命中该对手。
E3: 1级 | 步法 | F3: 你使用普通技之后可以无消耗的移动5尺，且不会触发借机攻击。
E4: 8级 | 登峰造极 | F4: 正统派的上升攻击后取消超级必杀技时，该场战斗剩余时间里上升攻击会造成双倍伤害。
D5: 邪修派 | E5: 1级 | 走火入魔 | F5: 你的所有攻击都会获得优势骰，所有受击都会陷入劣势骰。
B6: 1级 | 自在极意 | C6: 上升攻击作为武道者的核心技能，每场战斗中，每次成功使用会使其基础伤害增加2，但角色每次濒死/死亡/眩晕都会重置此修正，战斗结束后重置此修正。 | E6: 1级 | 修罗之道 | F6: 击杀会获得2+1d6的生命值恢复。溢出部分会转化为临时生命值。
E7: 1级 | 你再看看你后面呢 | F7: 你在对手身后/视野之外发动的进攻会获得额外10尺的距离。以此方法发动的攻击必定命中，攻击时会闪身到对手身旁。脆弱的对手会“受惊”。
E8: 1级 | 跑快快！ | F8: 邪修派武道者获得额外10尺的移动距离。
E9: 8级 | 彻底疯狂 | F9: 你释放超级必杀技后会陷入“修罗”状态：所有攻击必定会命中，所有受击也必定会命中。必杀技取消不会有伤害修正。角色濒死/死亡/眩晕后结束。战斗结束后也会结束此状态。
B10: 1级 | 气定神闲 | C10: 通过反应释放， 武道者受到徒手攻击伤害时可以获得一个1d4的伤害衰减修正。 | D10: 隐士 | E10: 1级 | 独门绝技 | F10: 隐士拥有自己的一个独门绝技（为角色基础必杀技，玩家可以自行设计），该技能对第一次见到的对手必定命中，且必定造成最大命中伤害，无法被反应。
E11: 1级 | 不被世人关注的存在感 | F11: 战斗中，如果隐士连续两回合没有造成和受到伤害，隐士会进入“隐身”。直到发起进攻，受到范围伤害，或者被隐身感知观察到。
E12: 8级 | 高级隐身 | F12: 隐士使用超级必杀技后会进入“高级隐身”，持续至多2个回合，其中即使造成和受到伤害也不会现身，且下次使用的独门绝技将会视为对手第一次见到此技。
A13: 军士 | B13: 1级 | 专业素养 | C13: 军士不会轻易受到言语上的挑衅，也不会受到魅惑。抵抗来自此类技能效果的减益会获得优势检定（=对手获得劣势检定）。 | D13: 技巧型 | E13: 1级 | 连续技 | F13: 每回合，对陷入特殊状态的对手可以使用一次无消耗的非OD版本必杀技。该必杀技会有(1d6 -熟练项调整)的惩罚。
E14: 1级 | 斗气连携 | F14: 使用OD必杀技之后的一回合内，所有OD技只会消耗1格斗气。
E15: 8级 | 完美谢幕 | F15: 你的超级必杀技必定命中特殊状态的敌人（包括强制倒地）。本场战斗中每次使用必杀技都会使超级必杀技增加2点伤害（且该部分伤害不会被修正影响）。
D16: 力量型 | E16: 1级 | 塔盾 | F16: 消耗80%的移动力。1个回合内，你会携带“霸体”。霸体状态角色的行动无法被反应。霸体角色受到的强制位移会被显著削弱。
B17: 1级 | 无间配合 | C17: 军士非常擅长协同作战。你命中其他队友打入特殊状态的敌人会将其击飞。如果是两个军士在一回合内命中同一个目标时，该敌人还会受到额外的1+1d6的伤害。 | E17: 1级 | 当身 | F17: 近战攻击命中你的“霸体状态”时，攻击者会受到一个等同于你轻攻击的伤害，并进行一个体质检定，如果检定失败，你对其下次攻击会处于优势。
E18: 1级 | 谁需要来一记重拳！ | F18: 你击飞的敌人会飞的更高。你造成特殊状态时，会对对手造成一个额外的（1d4+力量调整）的伤害。
E19: 8级 | 猛然冲击 | F19: 你的超级必杀技会给予你持续2回合的“霸体”。位于你超级必杀技释放路径/范围内的所有其他敌人都会受到30%的该超级必杀技伤害。
D20: 灵动型 | E20: 1级 | 奇袭 | F20: 你从与对手不同地形位置发起的进攻具有优势。你擅长在各种地形上移动（不会消耗额外移动力）。
B21: 1级 | 不屈 | C21: 军士受过严酷的意志力训练，体力值归0时不会倒地濒死而是继续作战。2回合内受到治疗，或者击杀1名敌人，则会从此状态恢复。再次受到伤害，或者2回合后如果未能取得击杀，则会直接死亡。不屈时，军士移动力减半，但攻击会获得优势命中。每场战斗可以重复触发。 | E21: 1级 | 飞檐走壁 | F21: 你可以在墙壁/天花板等类似地形停留最多一个回合。
E22: 1级 | 跑快快！ | F22: 速度型军士获得额外10尺的移动距离。
E23: 8级 | 红色delta强袭 | F23: 在特殊地形时：你可以在队友攻击后释放你的超级必杀技。若如此做，你的超级必杀技必定会命中对手，但是队友回合会就此结束，你可以开始一个新的回合。如果你是队伍中唯一存活的角色，你可以在任意角色行动时释放你的超级必杀技。
A24: 蛮勇斗士 | B24: 1级 | 暴力本能 | C24: 蛮勇斗士可以以一个附赠动作进入“狂暴”状态，每次长休后你可使用的狂暴次数等于（你的等级/3）+1。狂暴状态时，你的普通技都会等同于附带最大可使用狂暴状态次数的伤害；你的力量检定和力量豁免具有优势；拥有对轻/中攻击的抗性（受到伤害为50%）。“狂暴”状态的角色无法使用飞行道具。如果角色被击晕，强制倒地，或者一回合内未造成/受到伤害，狂暴状态解除。你也可以主动结束狂暴状态。 | D24: 摔角手 | E24: 1级 | 歌莉娅巨人 | F24: 你的“狂暴”会让你的身形变大。巨大化时受到位移效果显著降低；你可以轻松举起比你体型小的敌人，对这类敌人的指令投技能具有优势。会随着体型与对手体型的差值获得更多优势（由dm描述决定）。
E25: 1级 | 坦克引擎 | F25: 你的指令投系技能击杀对手时会获得3点最大生命值。
E26: 8级 | 大爆炸 | F26: 你的超级必杀技必定会命中体型小于你的敌人。在剩余战斗时间里你的体型会保持巨大化（可以与狂暴巨大叠加），且力量会直接升至21。
D27: 丛林猎手 | E27: 1级 | 猿神启动 | F27: 你的狂暴会让你身上流淌一种自然元素（毒，冰，火，电，选1），你的近战攻击会携带该元素效果并以该元素伤害作为额外狂暴伤害。
E28: 1级 | 野性 | F28: 你对敌人造成的元素效果伤害可以叠加，对手回合开始时会进行体质豁免检定，没有通过则会保留层数，通过则会重置。每个元素分别对应以下效果： a.毒：每回合受1d6+体质熟练的毒伤害。5层触发毒爆，对10尺内敌造成1d10+熟练毒伤害。 b.冰：每层减20%移动。5层触发冰暴，束缚10尺内敌造1d10+熟练伤害。 c.火：移动痕迹留火，对经过者造1d6+熟练燃烧伤。5层触发爆炸，造1d20+熟练伤害，火留3回合。 d.电：每层1d4+熟练闪电伤害。多带电敌人受连锁总层数伤害。场上总5层引发雷电猛击：眩晕1回并受1d10+熟练伤害。
B29: 1级 | 凶蛮重击 | C29: 你的普通技重击可以获得一个额外的伤害骰子（等同于该动作所使用的骰子）。8级时你可以再获得一个。 | E29: 8级 | 野性爆发 | F29: 使用超级必杀技后，你可以选择一种自然元素并保留该元素效果直至该场战斗结束，可以与猿神启动叠加（你可以选两个一样元素来达到双倍叠层，或者不同元素来达到多重效果）。
D30: 推土机 | E30: 1级 | 大力士 | F30: 你的“狂暴“会让你的所有攻击附带”击退“效果，无论是否造成伤害（但”挥空“时不会推开）。你的”击退“会与地形产生互动。击退的距离与攻击方式，攻击强度，和对手体型相关（由dm描述决定）。如果你攻击本身就附带特殊状态效果，则不会击退。对已经处于特殊状态（如浮空，倒地等）的角色产生的击退效果更强，与地形的互动也会更有效。
E31: 1级 | 几何学 | F31: 通过反应施放，如果附近有一名角色被击退到你附近你可以对他们再一次进行击退（可以随意选择方向），造成等同于他们上次击退受到的伤害。
E32: 8级 | 天崩地裂 | F32: 你的超级必杀技会在目标角色周围砸出一个直径20尺的圆形墙壁地形，持续到你或者目标死亡（可被破坏或者局部破坏）。如果在室内释放，则会将该部分区域强制转化为直径20尺的竞技场。所有与该墙壁互动的角色都会受到额外的1d6的伤害。
A33: 刽子手 | B33: 1级 | 最后一击 | C33: 每场战斗开始时刽子手会进行一个“处决”判定（1d4+力量熟练调整），如果刽子手的攻击使一名角色血量降低至该处决值以下，则会直接击杀该目标，并获得来自x公司的金钱提成（取决于击杀目标的价值）。 | D33: 刺杀者 | E33: 1级 | 终结标记 | F33: 你每次必杀技命中时都会获得1个1d6的“终结骰“，你可以在之后的必杀技命中时选择是否使用。使用时，会消耗所有已积攒的”终结骰“来对对手造成额外伤害。终结骰最多可以积攒5个。
E34: 1级 | 余罪赦免 | F34: 你受到致命伤害时，可以消耗所有的“终结骰“，你恢复到该数量的生命值。每次长休只能触发一次。
E35: 8级 | 终审 · 命定之死 | F35: 释放超级必杀技后，你所有的“终结骰“会升级成每个1d10的骰子，持续到战斗结束。
B36: 1级 | 背刺 | C36: 从身后/未被发现/先攻时发起的进攻会附带优势，并造成额外的1d6的伤害（每回合最多一次）。 | D36: 荣耀行刑官 | E36: 1级 | 镜花水月 | F36: 你可以在以下时机在20尺内的一个地方投放一个虚影。虚影受到攻击会被摧毁，并使攻击者“挥空”。挥空的对手无法取消此次普通技，且该回合内下次受击将处于“确反康”状态。 a)盛大登场：进入战斗时可以获得1回合的隐身，并创造一个虚影。 b)神出鬼没：每次触发“重击”或者“确反康”后可以进入1回合的隐身，并创造一个虚影。 c)夜行者：每次击杀后可以进入1回合的隐身，并创造一个虚影。
E37: 1级 | 保持酷爽 | F37: 你受到致命伤害时，会自动闪身到10尺处的一个较为安全的地方，并同时对攻击者释放一次必定“重击”的重攻击，生命值保持在1点。命中并击败对手后，你会恢复与所造成伤害等量的生命值。每次长休只能触发一次。
E38: 8级 | 狂舞终乐章 | F38: 你的超级必杀技会引爆全场，使目标20尺内所有角色陷入2回合“头晕目眩”状态：所有攻击都会“挥空”。所有以他们为目标的攻击都会具有优势。
A39: 牵制者 | B39: 1级 | 火力覆盖 | C39: 你的飞行道具系必杀技可以通过附赠动作释放。你飞行道具系必杀技的od版本只消耗1格斗气槽。 | D39: 重炮手 | E39: 1级 | 让子弹飞一会 | F39: 你所有的非od的飞行道具系必杀技会在你释放之后缓慢飞行，追踪并在对手回合开始时命中对手（在轮到其回合时进行命中及伤害判定）。所有在此期间提前触碰到的敌人会直接被该道具命中。
E40: 1级 | 范围轰炸 | F40: 你的飞行道具系必杀技会对命中对手及其附近3尺半径内所有敌人造成伤害，非直接命中的敌人受到一半伤害。
...
